Workbook

Sheet JANUARI
B6: REALISASI TARGET PNBP T.A. 2026
B7: BULAN JANUARI T.A. 2026
B10: NO | C10: JENIS PENERIMAAN | I10: DATA TARGET | L10: REALISASI | O10: PROSENTASE
I11: VOLUME | J11: TARIF | K11: TARGET (Rp.) | L11: VOLUME | M11: TARIF | N11: REALISASI (Rp.)
B12: 1 | C12: 2 | I12: 3 | J12: 4 | K12: 5 | L12: 3 | M12: 4 | N12: 5 | O12: 6
C13: 1 | D13: Pengujian untuk penerbitan Surat Izin Mengemudi (SIM) baru | I13: 1002980 | K13: =SUM(K14:K22) -> 106956030000 | L13: =SUM(L14:L22) -> 33484 | N13: =SUM(N14:N22) -> 3639520000 | O13: =N13/K13 -> 0.034028189
D14: a. | E14: Penerbitan SIM A | I14: 294130 | J14: 120000 | K14: =I14*J14 -> 35295600000 | L14: 12854 | M14: 120000 | N14: =L14*M14 -> 1542480000 | O14: =N14/K14 -> 0.043701765
D15: b. | E15: Penerbitan SIM B I | I15: 30304 | J15: 120000 | K15: =I15*J15 -> 3636480000 | L15: 1302 | M15: 120000 | N15: =L15*M15 -> 156240000 | O15: =N15/K15 -> 0.042964625
D16: c. | E16: Penerbitan SIM B II | I16: 13370 | J16: 120000 | K16: =I16*J16 -> 1604400000 | L16: 435 | M16: 120000 | N16: =L16*M16 -> 52200000 | O16: =N16/K16 -> 0.032535527
D17: d. | E17: Penerbitan SIM C | I17: 662649 | J17: 100000 | K17: =I17*J17 -> 66264900000 | L17: 18879 | M17: 100000 | N17: =L17*M17 -> 1887900000 | O17: =N17/K17 -> 0.028490196
D18: e. | E18: Penerbitan SIM C I | I18: 299 | J18: 100000 | K18: =I18*J18 -> 29900000 | L18: 0 | M18: 100000 | N18: =L18*M18 -> 0 | O18: =N18/K18 -> 0
D19: f. | E19: Penerbitan SIM C II | I19: 267 | J19: 100000 | K19: =I19*J19 -> 26700000 | L19: 0 | M19: 100000 | N19: =L19*M19 -> 0 | O19: =N19/K19 -> 0
D20: g. | E20: Penerbitan SIM D | I20: 1925 | J20: 50000 | K20: =I20*J20 -> 96250000 | L20: 14 | M20: 50000 | N20: =L20*M20 -> 700000 | O20: =N20/K20 -> 0.0072727273
D21: h. | E21: Penerbitan SIM D I | I21: 36 | J21: 50000 | K21: =I21*J21 -> 1800000 | L21: 0 | M21: 50000 | N21: =L21*M21 -> 0 | O21: =N21/K21 -> 0
D22: i. | E22: Pembuatan SIM International | I22: 0 | J22: 250000 | K22: =I22*J22 -> 0 | L22: 0 | M22: 250000 | N22: =L22*M22 -> 0 | O22: =N22/K22 -> #DIV/0!
C24: 2 | D24: Penerbitan Perpanjangan Surat Izin Mengemudi (SIM) | I24: 1997021 | K24: =SUM(K25:K33) -> 153240870000 | L24: =SUM(L25:L33) -> 111884 | N24: =SUM(N25:N33) -> 8584715000 | O24: =N24/K24 -> 0.056021054
D25: a. | E25: Penerbitan SIM A | I25: 596792 | J25: 80000 | K25: =I25*J25 -> 47743360000 | L25: 34726 | M25: 80000 | N25: =L25*M25 -> 2778080000 | O25: =N25/K25 -> 0.058187777
D26: b. | E26: Penerbitan SIM B I | I26: 63576 | J26: 80000 | K26: =I26*J26 -> 5086080000 | L26: 2511 | M26: 80000 | N26: =L26*M26 -> 200880000 | O26: =N26/K26 -> 0.039496036
D27: c. | E27: Penerbitan SIM B II | I27: 35983 | J27: 80000 | K27: =I27*J27 -> 2878640000 | L27: 1536 | M27: 80000 | N27: =L27*M27 -> 122880000 | O27: =N27/K27 -> 0.042686824
D28: d. | E28: Penerbitan SIM C | I28: 1296381 | J28: 75000 | K28: =I28*J28 -> 97228575000 | L28: 73101 | M28: 75000 | N28: =L28*M28 -> 5482575000 | O28: =N28/K28 -> 0.056388515
D29: e. | E29: Penerbitan SIM C I | I29: 3815 | J29: 75000 | K29: =I29*J29 -> 286125000 | L29: 0 | M29: 75000 | N29: =L29*M29 -> 0 | O29: =N29/K29 -> 0
D30: f. | E30: Penerbitan SIM C II | I30: 86 | J30: 75000 | K30: =I30*J30 -> 6450000 | L30: 0 | M30: 75000 | N30: =L30*M30 -> 0 | O30: =N30/K30 -> 0
D31: g. | E31: Penerbitan SIM D | I31: 360 | J31: 30000 | K31: =I31*J31 -> 10800000 | L31: 10 | M31: 30000 | N31: =L31*M31 -> 300000 | O31: =N31/K31 -> 0.027777778
D32: h. | E32: Penerbitan SIM D I | I32: 28 | J32: 30000 | K32: =I32*J32 -> 840000 | L32: 0 | M32: 30000 | N32: =L32*M32 -> 0 | O32: =N32/K32 -> 0
D33: i. | E33: Penerbitan SIM Internasional | I33: 0 | J33: 225000 | K33: =I33*J33 -> 0 | L33: 0 | M33: 225000 | N33: =L33*M33 -> 0
C35: 3 | D35: Penerbitan Surat Keterangan Uji Keterampilan Pengemudi (SKUKP) | I35: 100000 | J35: 50000 | K35: =I35*J35 -> 5000000000 | L35: 5619 | M35: 50000 | N35: =L35*M35 -> 280950000 | O35: =N35/K35 -> 0.05619
C37: 4 | D37: Penerbitan Surat Tanda Nomor Kendaraan Bermotor (STNK) | I37: 6000000 | K37: =+K38+K41 -> 727309900000 | L37: =L38+L41 -> 240344 | N37: =+N38+N41 -> 28202400000 | O37: =N37/K37 -> 0.038776318
D38: a. | E38: Kendaraan Bermotor roda 2 atau roda 3 | I38: 4726901 | K38: =SUM(K39:K40) -> 472690100000 | L38: =SUM(L39:L40) -> 198664 | N38: =SUM(N39:N40) -> 19866400000 | O38: =N38/K38 -> 0.042028382
E39: 1) | F39: Baru | I39: 2267860 | J39: 100000 | K39: =I39*J39 -> 226786000000 | L39: 53665 | M39: 100000 | N39: =L39*M39 -> 5366500000 | O39: =N39/K39 -> 0.023663277
E40: 2) | F40: Perpanjangan | I40: 2459041 | J40: 100000 | K40: =I40*J40 -> 245904100000 | L40: 144999 | M40: 100000 | N40: =L40*M40 -> 14499900000 | O40: =N40/K40 -> 0.05896567
D41: b. | E41: Kendaraan bermotor roda 4 atau lebih | I41: 1273099 | K41: =SUM(K42:K43) -> 254619800000 | L41: =SUM(L42:L43) -> 41680 | N41: =SUM(N42:N43) -> 8336000000 | O41: =N41/K41 -> 0.032739009
E42: 1) | F42: Baru | I42: 626781 | J42: 200000 | K42: =I42*J42 -> 125356200000 | L42: 6835 | M42: 200000 | N42: =L42*M42 -> 1367000000 | O42: =N42/K42 -> 0.010904925
E43: 2) | F43: Perpanjangan | I43: 646318 | J43: 200000 | K43: =I43*J43 -> 129263600000 | L43: 34845 | M43: 200000 | N43: =L43*M43 -> 6969000000 | O43: =N43/K43 -> 0.053913089
C45: 5 | D45: Penerbitan Tanda Nomor Kendaraan Bermotor (TNKB) | I45: 6000000 | K45: =SUM(K46,K47) -> 411586320000 | L45: =SUM(L46:L47) -> 234176 | N45: =SUM(N46,N47) -> 15689680000 | O45: =N45/K45 -> 0.038120023
D46: a. | E46: Kendaraan Bermotor Roda 2 atau 3 | I46: 4710342 | J46: 60000 | K46: =I46*J46 -> 282620520000 | L46: 193198 | M46: 60000 | N46: =L46*M46 -> 11591880000 | O46: =N46/K46 -> 0.041015705
D47: b. | E47: Kendaraan Bermotor Roda 4 atau lebih | I47: 1289658 | J47: 100000 | K47: =I47*J47 -> 128965800000 | L47: 40978 | M47: 100000 | N47: =L47*M47 -> 4097800000 | O47: =N47/K47 -> 0.031774315
C49: 6 | D49: Penerbitan Surat Tanda Coba Kendaraan Bermotor (STCK) | I49: 1500000 | K49: =SUM(K50:K51) -> 43861750000 | L49: =SUM(L50:L51) -> 61579 | N49: =SUM(N50:N51) -> 1726600000 | O49: =N49/K49 -> 0.039364594
D50: a. | E50: Kendaraan Bermotor Roda 2 atau 3 | I50: 1245530 | J50: 25000 | K50: =I50*J50 -> 31138250000 | L50: 54094 | M50: 25000 | N50: =L50*M50 -> 1352350000 | O50: =N50/K50 -> 0.043430507
D51: b. | E51: Kendaraan Bermotor Roda 4 atau lebih | I51: 254470 | J51: 50000 | K51: =I51*J51 -> 12723500000 | L51: 7485 | M51: 50000 | N51: =L51*M51 -> 374250000 | O51: =N51/K51 -> 0.029414076
C53: 7 | D53: Penerbitan Tanda Coba Kendaraan Bermotor (TCKB) | I53: 75000 | K53: =SUM(K54:K55) -> 5024800000 | L53: =SUM(L54:L55) -> 5225 | N53: =SUM(N54:N55) -> 367340000 | O53: =N53/K53 -> 0.073105397
...

Sheet FEB
B6: REALISASI TARGET PNBP T.A. 2026
B7: BULAN FEBRUARI T.A. 2026
B10: NO | C10: JENIS PENERIMAAN | I10: DATA TARGET | L10: REALISASI | O10: PROSENTASE
I11: VOLUME | J11: TARIF | K11: TARGET (Rp.) | L11: VOLUME | M11: TARIF | N11: REALISASI (Rp.)
B12: 1 | C12: 2 | I12: 3 | J12: 4 | K12: 5 | L12: 3 | M12: 4 | N12: 5 | O12: 6
C13: 1 | D13: Pengujian untuk penerbitan Surat Izin Mengemudi (SIM) baru | I13: 1002980 | K13: =SUM(K14:K22) -> 106956030000 | L13: =SUM(L14:L22) -> 22805 | N13: =SUM(N14:N22) -> 2473210000 | O13: =N13/K13 -> 0.023123614
D14: a. | E14: Penerbitan SIM A | I14: 294130 | J14: 120000 | K14: =I14*J14 -> 35295600000 | L14: 8519 | M14: 120000 | N14: =L14*M14 -> 1022280000 | O14: =N14/K14 -> 0.028963384
D15: b. | E15: Penerbitan SIM B I | I15: 30304 | J15: 120000 | K15: =I15*J15 -> 3636480000 | L15: 860 | M15: 120000 | N15: =L15*M15 -> 103200000 | O15: =N15/K15 -> 0.028379092
D16: c. | E16: Penerbitan SIM B II | I16: 13370 | J16: 120000 | K16: =I16*J16 -> 1604400000 | L16: 279 | M16: 120000 | N16: =L16*M16 -> 33480000 | O16: =N16/K16 -> 0.020867614
D17: d. | E17: Penerbitan SIM C | I17: 662649 | J17: 100000 | K17: =I17*J17 -> 66264900000 | L17: 13138 | M17: 100000 | N17: =L17*M17 -> 1313800000 | O17: =N17/K17 -> 0.019826484
D18: e. | E18: Penerbitan SIM C I | I18: 299 | J18: 100000 | K18: =I18*J18 -> 29900000 | L18: 0 | M18: 100000 | N18: =L18*M18 -> 0 | O18: =N18/K18 -> 0
D19: f. | E19: Penerbitan SIM C II | I19: 267 | J19: 100000 | K19: =I19*J19 -> 26700000 | L19: 0 | M19: 100000 | N19: =L19*M19 -> 0 | O19: =N19/K19 -> 0
D20: g. | E20: Penerbitan SIM D | I20: 1925 | J20: 50000 | K20: =I20*J20 -> 96250000 | L20: 8 | M20: 50000 | N20: =L20*M20 -> 400000 | O20: =N20/K20 -> 0.0041558442
D21: h. | E21: Penerbitan SIM D I | I21: 36 | J21: 50000 | K21: =I21*J21 -> 1800000 | L21: 1 | M21: 50000 | N21: =L21*M21 -> 50000 | O21: =N21/K21 -> 0.027777778
D22: i. | E22: Pembuatan SIM International | I22: 0 | J22: 250000 | K22: =I22*J22 -> 0 | L22: 0 | M22: 250000 | N22: =L22*M22 -> 0 | O22: =N22/K22 -> #DIV/0!
C24: 2 | D24: Penerbitan Perpanjangan Surat Izin Mengemudi (SIM) | I24: 1997021 | K24: =SUM(K25:K33) -> 153240870000 | L24: =SUM(L25:L33) -> 92570 | N24: =SUM(N25:N33) -> 7103075000 | O24: =N24/K24 -> 0.046352354
D25: a. | E25: Penerbitan SIM A | I25: 596792 | J25: 80000 | K25: =I25*J25 -> 47743360000 | L25: 28685 | M25: 80000 | N25: =L25*M25 -> 2294800000 | O25: =N25/K25 -> 0.048065323
D26: b. | E26: Penerbitan SIM B I | I26: 63576 | J26: 80000 | K26: =I26*J26 -> 5086080000 | L26: 2132 | M26: 80000 | N26: =L26*M26 -> 170560000 | O26: =N26/K26 -> 0.033534667
D27: c. | E27: Penerbitan SIM B II | I27: 35983 | J27: 80000 | K27: =I27*J27 -> 2878640000 | L27: 1365 | M27: 80000 | N27: =L27*M27 -> 109200000 | O27: =N27/K27 -> 0.03793458
D28: d. | E28: Penerbitan SIM C | I28: 1296381 | J28: 75000 | K28: =I28*J28 -> 97228575000 | L28: 60375 | M28: 75000 | N28: =L28*M28 -> 4528125000 | O28: =N28/K28 -> 0.046571957
D29: e. | E29: Penerbitan SIM C I | I29: 3815 | J29: 75000 | K29: =I29*J29 -> 286125000 | L29: 0 | M29: 75000 | N29: =L29*M29 -> 0 | O29: =N29/K29 -> 0
D30: f. | E30: Penerbitan SIM C II | I30: 86 | J30: 75000 | K30: =I30*J30 -> 6450000 | L30: 0 | M30: 75000 | N30: =L30*M30 -> 0 | O30: =N30/K30 -> 0
D31: g. | E31: Penerbitan SIM D | I31: 360 | J31: 30000 | K31: =I31*J31 -> 10800000 | L31: 13 | M31: 30000 | N31: =L31*M31 -> 390000 | O31: =N31/K31 -> 0.036111111
D32: h. | E32: Penerbitan SIM D I | I32: 28 | J32: 30000 | K32: =I32*J32 -> 840000 | L32: 0 | M32: 30000 | N32: =L32*M32 -> 0 | O32: =N32/K32 -> 0
D33: i. | E33: Penerbitan SIM Internasional | I33: 0 | J33: 225000 | K33: =I33*J33 -> 0 | L33: 0 | M33: 225000 | N33: =L33*M33 -> 0
C35: 3 | D35: Penerbitan Surat Keterangan Uji Keterampilan Pengemudi (SKUKP) | I35: 100000 | J35: 50000 | K35: =I35*J35 -> 5000000000 | L35: 4846 | M35: 50000 | N35: =L35*M35 -> 242300000 | O35: =N35/K35 -> 0.04846
C37: 4 | D37: Penerbitan Surat Tanda Nomor Kendaraan Bermotor (STNK) | I37: 6000000 | K37: =+K38+K41 -> 727309900000 | L37: =L38+L41 -> 216168 | N37: =+N38+N41 -> 25279900000 | O37: =N37/K37 -> 0.034758086
D38: a. | E38: Kendaraan Bermotor roda 2 atau roda 3 | I38: 4726901 | K38: =SUM(K39:K40) -> 472690100000 | L38: =SUM(L39:L40) -> 179537 | N38: =SUM(N39:N40) -> 17953700000 | O38: =N38/K38 -> 0.037981967
E39: 1) | F39: Baru | I39: 2267860 | J39: 100000 | K39: =I39*J39 -> 226786000000 | L39: 53714 | M39: 100000 | N39: =L39*M39 -> 5371400000 | O39: =N39/K39 -> 0.023684884
E40: 2) | F40: Perpanjangan | I40: 2459041 | J40: 100000 | K40: =I40*J40 -> 245904100000 | L40: 125823 | M40: 100000 | N40: =L40*M40 -> 12582300000 | O40: =N40/K40 -> 0.051167508
D41: b. | E41: Kendaraan bermotor roda 4 atau lebih | I41: 1273099 | K41: =SUM(K42:K43) -> 254619800000 | L41: =SUM(L42:L43) -> 36631 | N41: =SUM(N42:N43) -> 7326200000 | O41: =N41/K41 -> 0.028773096
E42: 1) | F42: Baru | I42: 626781 | J42: 200000 | K42: =I42*J42 -> 125356200000 | L42: 6006 | M42: 200000 | N42: =L42*M42 -> 1201200000 | O42: =N42/K42 -> 0.0095822943
E43: 2) | F43: Perpanjangan | I43: 646318 | J43: 200000 | K43: =I43*J43 -> 129263600000 | L43: 30625 | M43: 200000 | N43: =L43*M43 -> 6125000000 | O43: =N43/K43 -> 0.047383796
C45: 5 | D45: Penerbitan Tanda Nomor Kendaraan Bermotor (TNKB) | I45: 6000000 | K45: =SUM(K46,K47) -> 411586320000 | L45: =SUM(L46:L47) -> 211012 | N45: =SUM(N46,N47) -> 14101560000 | O45: =N45/K45 -> 0.034261489
D46: a. | E46: Kendaraan Bermotor Roda 2 atau 3 | I46: 4710342 | J46: 60000 | K46: =I46*J46 -> 282620520000 | L46: 174991 | M46: 60000 | N46: =L46*M46 -> 10499460000 | O46: =N46/K46 -> 0.037150381
D47: b. | E47: Kendaraan Bermotor Roda 4 atau lebih | I47: 1289658 | J47: 100000 | K47: =I47*J47 -> 128965800000 | L47: 36021 | M47: 100000 | N47: =L47*M47 -> 3602100000 | O47: =N47/K47 -> 0.027930661
C49: 6 | D49: Penerbitan Surat Tanda Coba Kendaraan Bermotor (STCK) | I49: 1500000 | K49: =SUM(K50:K51) -> 43861750000 | L49: =SUM(L50:L51) -> 59920 | N49: =SUM(N50:N51) -> 1656575000 | O49: =N49/K49 -> 0.037768101
D50: a. | E50: Kendaraan Bermotor Roda 2 atau 3 | I50: 1245530 | J50: 25000 | K50: =I50*J50 -> 31138250000 | L50: 53577 | M50: 25000 | N50: =L50*M50 -> 1339425000 | O50: =N50/K50 -> 0.043015423
D51: b. | E51: Kendaraan Bermotor Roda 4 atau lebih | I51: 254470 | J51: 50000 | K51: =I51*J51 -> 12723500000 | L51: 6343 | M51: 50000 | N51: =L51*M51 -> 317150000 | O51: =N51/K51 -> 0.024926317
C53: 7 | D53: Penerbitan Tanda Coba Kendaraan Bermotor (TCKB) | I53: 75000 | K53: =SUM(K54:K55) -> 5024800000 | L53: =SUM(L54:L55) -> 4533 | N53: =SUM(N54:N55) -> 313260000 | O53: =N53/K53 -> 0.06234278
...

Sheet MARET
B6: REALISASI TARGET PNBP T.A. 2026
B7: BULAN MARET T.A. 2026
B10: NO | C10: JENIS PENERIMAAN | I10: DATA TARGET | L10: REALISASI | O10: PROSENTASE
I11: VOLUME | J11: TARIF | K11: TARGET (Rp.) | L11: VOLUME | M11: TARIF | N11: REALISASI (Rp.)
B12: 1 | C12: 2 | I12: 3 | J12: 4 | K12: 5 | L12: 3 | M12: 4 | N12: 5 | O12: 6
C13: 1 | D13: Pengujian untuk penerbitan Surat Izin Mengemudi (SIM) baru | I13: 1002980 | K13: =SUM(K14:K22) -> 106956030000 | L13: =SUM(L14:L22) -> 22840 | N13: =SUM(N14:N22) -> 2493030000 | O13: =N13/K13 -> 0.023308924
D14: a. | E14: Penerbitan SIM A | I14: 294130 | J14: 120000 | K14: =I14*J14 -> 35295600000 | L14: 9321 | M14: 120000 | N14: =L14*M14 -> 1118520000 | O14: =N14/K14 -> 0.031690069
D15: b. | E15: Penerbitan SIM B I | I15: 30304 | J15: 120000 | K15: =I15*J15 -> 3636480000 | L15: 834 | M15: 120000 | N15: =L15*M15 -> 100080000 | O15: =N15/K15 -> 0.027521119
D16: c. | E16: Penerbitan SIM B II | I16: 13370 | J16: 120000 | K16: =I16*J16 -> 1604400000 | L16: 324 | M16: 120000 | N16: =L16*M16 -> 38880000 | O16: =N16/K16 -> 0.024233358
D17: d. | E17: Penerbitan SIM C | I17: 662649 | J17: 100000 | K17: =I17*J17 -> 66264900000 | L17: 12348 | M17: 100000 | N17: =L17*M17 -> 1234800000 | O17: =N17/K17 -> 0.0186343
D18: e. | E18: Penerbitan SIM C I | I18: 299 | J18: 100000 | K18: =I18*J18 -> 29900000 | L18: 2 | M18: 100000 | N18: =L18*M18 -> 200000 | O18: =N18/K18 -> 0.0066889632
D19: f. | E19: Penerbitan SIM C II | I19: 267 | J19: 100000 | K19: =I19*J19 -> 26700000 | L19: 0 | M19: 100000 | N19: =L19*M19 -> 0 | O19: =N19/K19 -> 0
D20: g. | E20: Penerbitan SIM D | I20: 1925 | J20: 50000 | K20: =I20*J20 -> 96250000 | L20: 11 | M20: 50000 | N20: =L20*M20 -> 550000 | O20: =N20/K20 -> 0.0057142857
D21: h. | E21: Penerbitan SIM D I | I21: 36 | J21: 50000 | K21: =I21*J21 -> 1800000 | L21: 0 | M21: 50000 | N21: =L21*M21 -> 0 | O21: =N21/K21 -> 0
D22: i. | E22: Pembuatan SIM International | I22: 0 | J22: 250000 | K22: =I22*J22 -> 0 | L22: 0 | M22: 250000 | N22: =L22*M22 -> 0 | O22: =N22/K22 -> #DIV/0!
C24: 2 | D24: Penerbitan Perpanjangan Surat Izin Mengemudi (SIM) | I24: 1997021 | K24: =SUM(K25:K33) -> 153240870000 | L24: =SUM(L25:L33) -> 107926 | N24: =SUM(N25:N33) -> 8282995000 | O24: =N24/K24 -> 0.054052127
D25: a. | E25: Penerbitan SIM A | I25: 596792 | J25: 80000 | K25: =I25*J25 -> 47743360000 | L25: 33838 | M25: 80000 | N25: =L25*M25 -> 2707040000 | O25: =N25/K25 -> 0.056699822
D26: b. | E26: Penerbitan SIM B I | I26: 63576 | J26: 80000 | K26: =I26*J26 -> 5086080000 | L26: 2433 | M26: 80000 | N26: =L26*M26 -> 194640000 | O26: =N26/K26 -> 0.038269158
D27: c. | E27: Penerbitan SIM B II | I27: 35983 | J27: 80000 | K27: =I27*J27 -> 2878640000 | L27: 1546 | M27: 80000 | N27: =L27*M27 -> 123680000 | O27: =N27/K27 -> 0.042964733
D28: d. | E28: Penerbitan SIM C | I28: 1296381 | J28: 75000 | K28: =I28*J28 -> 97228575000 | L28: 70097 | M28: 75000 | N28: =L28*M28 -> 5257275000 | O28: =N28/K28 -> 0.054071295
D29: e. | E29: Penerbitan SIM C I | I29: 3815 | J29: 75000 | K29: =I29*J29 -> 286125000 | L29: 0 | M29: 75000 | N29: =L29*M29 -> 0 | O29: =N29/K29 -> 0
D30: f. | E30: Penerbitan SIM C II | I30: 86 | J30: 75000 | K30: =I30*J30 -> 6450000 | L30: 0 | M30: 75000 | N30: =L30*M30 -> 0 | O30: =N30/K30 -> 0
D31: g. | E31: Penerbitan SIM D | I31: 360 | J31: 30000 | K31: =I31*J31 -> 10800000 | L31: 11 | M31: 30000 | N31: =L31*M31 -> 330000 | O31: =N31/K31 -> 0.030555556
D32: h. | E32: Penerbitan SIM D I | I32: 28 | J32: 30000 | K32: =I32*J32 -> 840000 | L32: 1 | M32: 30000 | N32: =L32*M32 -> 30000 | O32: =N32/K32 -> 0.035714286
D33: i. | E33: Penerbitan SIM Internasional | I33: 0 | J33: 225000 | K33: =I33*J33 -> 0 | L33: 0 | M33: 225000 | N33: =L33*M33 -> 0
C35: 3 | D35: Penerbitan Surat Keterangan Uji Keterampilan Pengemudi (SKUKP) | I35: 100000 | J35: 50000 | K35: =I35*J35 -> 5000000000 | L35: 5207 | M35: 50000 | N35: =L35*M35 -> 260350000 | O35: =N35/K35 -> 0.05207
C37: 4 | D37: Penerbitan Surat Tanda Nomor Kendaraan Bermotor (STNK) | I37: 6000000 | K37: =+K38+K41 -> 727309900000 | L37: =L38+L41 -> 216108 | N37: =+N38+N41 -> 25201200000 | O37: =N37/K37 -> 0.034649879
D38: a. | E38: Kendaraan Bermotor roda 2 atau roda 3 | I38: 4726901 | K38: =SUM(K39:K40) -> 472690100000 | L38: =SUM(L39:L40) -> 180204 | N38: =SUM(N39:N40) -> 18020400000 | O38: =N38/K38 -> 0.038123075
E39: 1) | F39: Baru | I39: 2267860 | J39: 100000 | K39: =I39*J39 -> 226786000000 | L39: 53613 | M39: 100000 | N39: =L39*M39 -> 5361300000 | O39: =N39/K39 -> 0.023640348
E40: 2) | F40: Perpanjangan | I40: 2459041 | J40: 100000 | K40: =I40*J40 -> 245904100000 | L40: 126591 | M40: 100000 | N40: =L40*M40 -> 12659100000 | O40: =N40/K40 -> 0.051479825
D41: b. | E41: Kendaraan bermotor roda 4 atau lebih | I41: 1273099 | K41: =SUM(K42:K43) -> 254619800000 | L41: =SUM(L42:L43) -> 35904 | N41: =SUM(N42:N43) -> 7180800000 | O41: =N41/K41 -> 0.028202049
E42: 1) | F42: Baru | I42: 626781 | J42: 200000 | K42: =I42*J42 -> 125356200000 | L42: 5943 | M42: 200000 | N42: =L42*M42 -> 1188600000 | O42: =N42/K42 -> 0.0094817807
E43: 2) | F43: Perpanjangan | I43: 646318 | J43: 200000 | K43: =I43*J43 -> 129263600000 | L43: 29961 | M43: 200000 | N43: =L43*M43 -> 5992200000 | O43: =N43/K43 -> 0.046356438
C45: 5 | D45: Penerbitan Tanda Nomor Kendaraan Bermotor (TNKB) | I45: 6000000 | K45: =SUM(K46,K47) -> 411586320000 | L45: =SUM(L46:L47) -> 212003 | N45: =SUM(N46,N47) -> 14136420000 | O45: =N45/K45 -> 0.034346185
D46: a. | E46: Kendaraan Bermotor Roda 2 atau 3 | I46: 4710342 | J46: 60000 | K46: =I46*J46 -> 282620520000 | L46: 176597 | M46: 60000 | N46: =L46*M46 -> 10595820000 | O46: =N46/K46 -> 0.037491333
D47: b. | E47: Kendaraan Bermotor Roda 4 atau lebih | I47: 1289658 | J47: 100000 | K47: =I47*J47 -> 128965800000 | L47: 35406 | M47: 100000 | N47: =L47*M47 -> 3540600000 | O47: =N47/K47 -> 0.02745379
C49: 6 | D49: Penerbitan Surat Tanda Coba Kendaraan Bermotor (STCK) | I49: 1500000 | K49: =SUM(K50:K51) -> 43861750000 | L49: =SUM(L50:L51) -> 59633 | N49: =SUM(N50:N51) -> 1646300000 | O49: =N49/K49 -> 0.037533842
D50: a. | E50: Kendaraan Bermotor Roda 2 atau 3 | I50: 1245530 | J50: 25000 | K50: =I50*J50 -> 31138250000 | L50: 53414 | M50: 25000 | N50: =L50*M50 -> 1335350000 | O50: =N50/K50 -> 0.042884555
D51: b. | E51: Kendaraan Bermotor Roda 4 atau lebih | I51: 254470 | J51: 50000 | K51: =I51*J51 -> 12723500000 | L51: 6219 | M51: 50000 | N51: =L51*M51 -> 310950000 | O51: =N51/K51 -> 0.02443903
C53: 7 | D53: Penerbitan Tanda Coba Kendaraan Bermotor (TCKB) | I53: 75000 | K53: =SUM(K54:K55) -> 5024800000 | L53: =SUM(L54:L55) -> 4734 | N53: =SUM(N54:N55) -> 329200000 | O53: =N53/K53 -> 0.065515045
...

Sheet APRIL
B6: REALISASI TARGET PNBP T.A. 2026
B7: BULAN APRIL T.A. 2026
B10: NO | C10: JENIS PENERIMAAN | I10: DATA TARGET | L10: REALISASI | O10: PROSENTASE
I11: VOLUME | J11: TARIF | K11: TARGET (Rp.) | L11: VOLUME | M11: TARIF | N11: REALISASI (Rp.)
B12: 1 | C12: 2 | I12: 3 | J12: 4 | K12: 5 | L12: 3 | M12: 4 | N12: 5 | O12: 6
C13: 1 | D13: Pengujian untuk penerbitan Surat Izin Mengemudi (SIM) baru | I13: 1002980 | K13: =SUM(K14:K22) -> 106956030000 | L13: =SUM(L14:L22) -> 36246 | N13: =SUM(N14:N22) -> 3933500000 | O13: =N13/K13 -> 0.036776795
D14: a. | E14: Penerbitan SIM A | I14: 294130 | J14: 120000 | K14: =I14*J14 -> 35295600000 | L14: 13251 | M14: 120000 | N14: =L14*M14 -> 1590120000 | O14: =N14/K14 -> 0.045051508
D15: b. | E15: Penerbitan SIM B I | I15: 30304 | J15: 120000 | K15: =I15*J15 -> 3636480000 | L15: 1677 | M15: 120000 | N15: =L15*M15 -> 201240000 | O15: =N15/K15 -> 0.055339229
D16: c. | E16: Penerbitan SIM B II | I16: 13370 | J16: 120000 | K16: =I16*J16 -> 1604400000 | L16: 527 | M16: 120000 | N16: =L16*M16 -> 63240000 | O16: =N16/K16 -> 0.039416604
D17: d. | E17: Penerbitan SIM C | I17: 662649 | J17: 100000 | K17: =I17*J17 -> 66264900000 | L17: 20781 | M17: 100000 | N17: =L17*M17 -> 2078100000 | O17: =N17/K17 -> 0.031360494
D18: e. | E18: Penerbitan SIM C I | I18: 299 | J18: 100000 | K18: =I18*J18 -> 29900000 | L18: 6 | M18: 100000 | N18: =L18*M18 -> 600000 | O18: =N18/K18 -> 0.02006689
D19: f. | E19: Penerbitan SIM C II | I19: 267 | J19: 100000 | K19: =I19*J19 -> 26700000 | L19: 0 | M19: 100000 | N19: =L19*M19 -> 0 | O19: =N19/K19 -> 0
D20: g. | E20: Penerbitan SIM D | I20: 1925 | J20: 50000 | K20: =I20*J20 -> 96250000 | L20: 3 | M20: 50000 | N20: =L20*M20 -> 150000 | O20: =N20/K20 -> 0.0015584416
D21: h. | E21: Penerbitan SIM D I | I21: 36 | J21: 50000 | K21: =I21*J21 -> 1800000 | L21: 1 | M21: 50000 | N21: =L21*M21 -> 50000 | O21: =N21/K21 -> 0.027777778
D22: i. | E22: Pembuatan SIM International | I22: 0 | J22: 250000 | K22: =I22*J22 -> 0 | L22: 0 | M22: 250000 | N22: =L22*M22 -> 0 | O22: =N22/K22 -> #DIV/0!
C24: 2 | D24: Penerbitan Perpanjangan Surat Izin Mengemudi (SIM) | I24: 1997021 | K24: =SUM(K25:K33) -> 153240870000 | L24: =SUM(L25:L33) -> 125380 | N24: =SUM(N25:N33) -> 9622120000 | O24: =N24/K24 -> 0.062790821
D25: a. | E25: Penerbitan SIM A | I25: 596792 | J25: 80000 | K25: =I25*J25 -> 47743360000 | L25: 39234 | M25: 80000 | N25: =L25*M25 -> 3138720000 | O25: =N25/K25 -> 0.065741498
D26: b. | E26: Penerbitan SIM B I | I26: 63576 | J26: 80000 | K26: =I26*J26 -> 5086080000 | L26: 2805 | M26: 80000 | N26: =L26*M26 -> 224400000 | O26: =N26/K26 -> 0.044120423
D27: c. | E27: Penerbitan SIM B II | I27: 35983 | J27: 80000 | K27: =I27*J27 -> 2878640000 | L27: 1784 | M27: 80000 | N27: =L27*M27 -> 142720000 | O27: =N27/K27 -> 0.049578968
D28: d. | E28: Penerbitan SIM C | I28: 1296381 | J28: 75000 | K28: =I28*J28 -> 97228575000 | L28: 81517 | M28: 75000 | N28: =L28*M28 -> 6113775000 | O28: =N28/K28 -> 0.062880434
D29: e. | E29: Penerbitan SIM C I | I29: 3815 | J29: 75000 | K29: =I29*J29 -> 286125000 | L29: 29 | M29: 75000 | N29: =L29*M29 -> 2175000 | O29: =N29/K29 -> 0.0076015727
D30: f. | E30: Penerbitan SIM C II | I30: 86 | J30: 75000 | K30: =I30*J30 -> 6450000 | L30: 0 | M30: 75000 | N30: =L30*M30 -> 0 | O30: =N30/K30 -> 0
D31: g. | E31: Penerbitan SIM D | I31: 360 | J31: 30000 | K31: =I31*J31 -> 10800000 | L31: 11 | M31: 30000 | N31: =L31*M31 -> 330000 | O31: =N31/K31 -> 0.030555556
D32: h. | E32: Penerbitan SIM D I | I32: 28 | J32: 30000 | K32: =I32*J32 -> 840000 | L32: 0 | M32: 30000 | N32: =L32*M32 -> 0 | O32: =N32/K32 -> 0
D33: i. | E33: Penerbitan SIM Internasional | I33: 0 | J33: 225000 | K33: =I33*J33 -> 0 | L33: 0 | M33: 225000 | N33: =L33*M33 -> 0
C35: 3 | D35: Penerbitan Surat Keterangan Uji Keterampilan Pengemudi (SKUKP) | I35: 100000 | J35: 50000 | K35: =I35*J35 -> 5000000000 | L35: 6804 | M35: 50000 | N35: =L35*M35 -> 340200000 | O35: =N35/K35 -> 0.06804
C37: 4 | D37: Penerbitan Surat Tanda Nomor Kendaraan Bermotor (STNK) | I37: 6000000 | K37: =+K38+K41 -> 727309900000 | L37: =L38+L41 -> 268498 | N37: =+N38+N41 -> 31460000000 | O37: =N37/K37 -> 0.043255289
D38: a. | E38: Kendaraan Bermotor roda 2 atau roda 3 | I38: 4726901 | K38: =SUM(K39:K40) -> 472690100000 | L38: =SUM(L39:L40) -> 222396 | N38: =SUM(N39:N40) -> 22239600000 | O38: =N38/K38 -> 0.047049007
E39: 1) | F39: Baru | I39: 2267860 | J39: 100000 | K39: =I39*J39 -> 226786000000 | L39: 61032 | M39: 100000 | N39: =L39*M39 -> 6103200000 | O39: =N39/K39 -> 0.026911714
E40: 2) | F40: Perpanjangan | I40: 2459041 | J40: 100000 | K40: =I40*J40 -> 245904100000 | L40: 161364 | M40: 100000 | N40: =L40*M40 -> 16136400000 | O40: =N40/K40 -> 0.065620703
D41: b. | E41: Kendaraan bermotor roda 4 atau lebih | I41: 1273099 | K41: =SUM(K42:K43) -> 254619800000 | L41: =SUM(L42:L43) -> 46102 | N41: =SUM(N42:N43) -> 9220400000 | O41: =N41/K41 -> 0.036212423
E42: 1) | F42: Baru | I42: 626781 | J42: 200000 | K42: =I42*J42 -> 125356200000 | L42: 6578 | M42: 200000 | N42: =L42*M42 -> 1315600000 | O42: =N42/K42 -> 0.010494894
E43: 2) | F43: Perpanjangan | I43: 646318 | J43: 200000 | K43: =I43*J43 -> 129263600000 | L43: 39524 | M43: 200000 | N43: =L43*M43 -> 7904800000 | O43: =N43/K43 -> 0.06115256
C45: 5 | D45: Penerbitan Tanda Nomor Kendaraan Bermotor (TNKB) | I45: 6000000 | K45: =SUM(K46,K47) -> 411586320000 | L45: =SUM(L46:L47) -> 262184 | N45: =SUM(N46,N47) -> 17547120000 | O45: =N45/K45 -> 0.042632904
D46: a. | E46: Kendaraan Bermotor Roda 2 atau 3 | I46: 4710342 | J46: 60000 | K46: =I46*J46 -> 282620520000 | L46: 216782 | M46: 60000 | N46: =L46*M46 -> 13006920000 | O46: =N46/K46 -> 0.046022561
D47: b. | E47: Kendaraan Bermotor Roda 4 atau lebih | I47: 1289658 | J47: 100000 | K47: =I47*J47 -> 128965800000 | L47: 45402 | M47: 100000 | N47: =L47*M47 -> 4540200000 | O47: =N47/K47 -> 0.035204682
C49: 6 | D49: Penerbitan Surat Tanda Coba Kendaraan Bermotor (STCK) | I49: 1500000 | K49: =SUM(K50:K51) -> 43861750000 | L49: =SUM(L50:L51) -> 68032 | N49: =SUM(N50:N51) -> 1874600000 | O49: =N49/K49 -> 0.042738833
D50: a. | E50: Kendaraan Bermotor Roda 2 atau 3 | I50: 1245530 | J50: 25000 | K50: =I50*J50 -> 31138250000 | L50: 61080 | M50: 25000 | N50: =L50*M50 -> 1527000000 | O50: =N50/K50 -> 0.049039365
D51: b. | E51: Kendaraan Bermotor Roda 4 atau lebih | I51: 254470 | J51: 50000 | K51: =I51*J51 -> 12723500000 | L51: 6952 | M51: 50000 | N51: =L51*M51 -> 347600000 | O51: =N51/K51 -> 0.027319527
C53: 7 | D53: Penerbitan Tanda Coba Kendaraan Bermotor (TCKB) | I53: 75000 | K53: =SUM(K54:K55) -> 5024800000 | L53: =SUM(L54:L55) -> 5503 | N53: =SUM(N54:N55) -> 382340000 | O53: =N53/K53 -> 0.076090591
...

Sheet MEI
B6: REALISASI TARGET PNBP T.A. 2026
B7: BULAN MEI T.A. 2026
B10: NO | C10: JENIS PENERIMAAN | I10: DATA TARGET | L10: REALISASI | O10: PROSENTASE
I11: VOLUME | J11: TARIF | K11: TARGET (Rp.) | L11: VOLUME | M11: TARIF | N11: REALISASI (Rp.)
B12: 1 | C12: 2 | I12: 3 | J12: 4 | K12: 5 | L12: 3 | M12: 4 | N12: 5 | O12: 6
C13: 1 | D13: Pengujian untuk penerbitan Surat Izin Mengemudi (SIM) baru | I13: 1002980 | K13: =SUM(K14:K22) -> 106956030000 | L13: =SUM(L14:L22) -> 31200 | N13: =SUM(N14:N22) -> 3383700000 | O13: =N13/K13 -> 0.031636365
D14: a. | E14: Penerbitan SIM A | I14: 294130 | J14: 120000 | K14: =I14*J14 -> 35295600000 | L14: 11276 | M14: 120000 | N14: =L14*M14 -> 1353120000 | O14: =N14/K14 -> 0.03833679
D15: b. | E15: Penerbitan SIM B I | I15: 30304 | J15: 120000 | K15: =I15*J15 -> 3636480000 | L15: 1442 | M15: 120000 | N15: =L15*M15 -> 173040000 | O15: =N15/K15 -> 0.047584477
D16: c. | E16: Penerbitan SIM B II | I16: 13370 | J16: 120000 | K16: =I16*J16 -> 1604400000 | L16: 502 | M16: 120000 | N16: =L16*M16 -> 60240000 | O16: =N16/K16 -> 0.037546746
D17: d. | E17: Penerbitan SIM C | I17: 662649 | J17: 100000 | K17: =I17*J17 -> 66264900000 | L17: 17963 | M17: 100000 | N17: =L17*M17 -> 1796300000 | O17: =N17/K17 -> 0.027107866
D18: e. | E18: Penerbitan SIM C I | I18: 299 | J18: 100000 | K18: =I18*J18 -> 29900000 | L18: 3 | M18: 100000 | N18: =L18*M18 -> 300000 | O18: =N18/K18 -> 0.010033445
D19: f. | E19: Penerbitan SIM C II | I19: 267 | J19: 100000 | K19: =I19*J19 -> 26700000 | L19: 0 | M19: 100000 | N19: =L19*M19 -> 0 | O19: =N19/K19 -> 0
D20: g. | E20: Penerbitan SIM D | I20: 1925 | J20: 50000 | K20: =I20*J20 -> 96250000 | L20: 14 | M20: 50000 | N20: =L20*M20 -> 700000 | O20: =N20/K20 -> 0.0072727273
D21: h. | E21: Penerbitan SIM D I | I21: 36 | J21: 50000 | K21: =I21*J21 -> 1800000 | L21: 0 | M21: 50000 | N21: =L21*M21 -> 0 | O21: =N21/K21 -> 0
D22: i. | E22: Pembuatan SIM International | I22: 0 | J22: 250000 | K22: =I22*J22 -> 0 | L22: 0 | M22: 250000 | N22: =L22*M22 -> 0 | O22: =N22/K22 -> #DIV/0!
C24: 2 | D24: Penerbitan Perpanjangan Surat Izin Mengemudi (SIM) | I24: 1997021 | K24: =SUM(K25:K33) -> 153240870000 | L24: =SUM(L25:L33) -> 113577 | N24: =SUM(N25:N33) -> 8715480000 | O24: =N24/K24 -> 0.056874383
D25: a. | E25: Penerbitan SIM A | I25: 596792 | J25: 80000 | K25: =I25*J25 -> 47743360000 | L25: 35513 | M25: 80000 | N25: =L25*M25 -> 2841040000 | O25: =N25/K25 -> 0.059506495
D26: b. | E26: Penerbitan SIM B I | I26: 63576 | J26: 80000 | K26: =I26*J26 -> 5086080000 | L26: 2361 | M26: 80000 | N26: =L26*M26 -> 188880000 | O26: =N26/K26 -> 0.037136655
D27: c. | E27: Penerbitan SIM B II | I27: 35983 | J27: 80000 | K27: =I27*J27 -> 2878640000 | L27: 1612 | M27: 80000 | N27: =L27*M27 -> 128960000 | O27: =N27/K27 -> 0.044798933
D28: d. | E28: Penerbitan SIM C | I28: 1296381 | J28: 75000 | K28: =I28*J28 -> 97228575000 | L28: 74086 | M28: 75000 | N28: =L28*M28 -> 5556450000 | O28: =N28/K28 -> 0.057148323
D29: e. | E29: Penerbitan SIM C I | I29: 3815 | J29: 75000 | K29: =I29*J29 -> 286125000 | L29: 0 | M29: 75000 | N29: =L29*M29 -> 0 | O29: =N29/K29 -> 0
D30: f. | E30: Penerbitan SIM C II | I30: 86 | J30: 75000 | K30: =I30*J30 -> 6450000 | L30: 0 | M30: 75000 | N30: =L30*M30 -> 0 | O30: =N30/K30 -> 0
D31: g. | E31: Penerbitan SIM D | I31: 360 | J31: 30000 | K31: =I31*J31 -> 10800000 | L31: 5 | M31: 30000 | N31: =L31*M31 -> 150000 | O31: =N31/K31 -> 0.013888889
D32: h. | E32: Penerbitan SIM D I | I32: 28 | J32: 30000 | K32: =I32*J32 -> 840000 | L32: 0 | M32: 30000 | N32: =L32*M32 -> 0 | O32: =N32/K32 -> 0
D33: i. | E33: Penerbitan SIM Internasional | I33: 0 | J33: 225000 | K33: =I33*J33 -> 0 | L33: 0 | M33: 225000 | N33: =L33*M33 -> 0
C35: 3 | D35: Penerbitan Surat Keterangan Uji Keterampilan Pengemudi (SKUKP) | I35: 100000 | J35: 50000 | K35: =I35*J35 -> 5000000000 | L35: 5682 | M35: 50000 | N35: =L35*M35 -> 284100000 | O35: =N35/K35 -> 0.05682
C37: 4 | D37: Penerbitan Surat Tanda Nomor Kendaraan Bermotor (STNK) | I37: 6000000 | K37: =+K38+K41 -> 727309900000 | L37: =L38+L41 -> 229557 | N37: =+N38+N41 -> 27063600000 | O37: =N37/K37 -> 0.037210548
D38: a. | E38: Kendaraan Bermotor roda 2 atau roda 3 | I38: 4726901 | K38: =SUM(K39:K40) -> 472690100000 | L38: =SUM(L39:L40) -> 188478 | N38: =SUM(N39:N40) -> 18847800000 | O38: =N38/K38 -> 0.039873482
E39: 1) | F39: Baru | I39: 2267860 | J39: 100000 | K39: =I39*J39 -> 226786000000 | L39: 46460 | M39: 100000 | N39: =L39*M39 -> 4646000000 | O39: =N39/K39 -> 0.020486273
E40: 2) | F40: Perpanjangan | I40: 2459041 | J40: 100000 | K40: =I40*J40 -> 245904100000 | L40: 142018 | M40: 100000 | N40: =L40*M40 -> 14201800000 | O40: =N40/K40 -> 0.057753409
D41: b. | E41: Kendaraan bermotor roda 4 atau lebih | I41: 1273099 | K41: =SUM(K42:K43) -> 254619800000 | L41: =SUM(L42:L43) -> 41079 | N41: =SUM(N42:N43) -> 8215800000 | O41: =N41/K41 -> 0.032266933
E42: 1) | F42: Baru | I42: 626781 | J42: 200000 | K42: =I42*J42 -> 125356200000 | L42: 5559 | M42: 200000 | N42: =L42*M42 -> 1111800000 | O42: =N42/K42 -> 0.0088691265
E43: 2) | F43: Perpanjangan | I43: 646318 | J43: 200000 | K43: =I43*J43 -> 129263600000 | L43: 35520 | M43: 200000 | N43: =L43*M43 -> 7104000000 | O43: =N43/K43 -> 0.054957467
C45: 5 | D45: Penerbitan Tanda Nomor Kendaraan Bermotor (TNKB) | I45: 6000000 | K45: =SUM(K46,K47) -> 411586320000 | L45: =SUM(L46:L47) -> 224468 | N45: =SUM(N46,N47) -> 15089080000 | O45: =N45/K45 -> 0.036660791
D46: a. | E46: Kendaraan Bermotor Roda 2 atau 3 | I46: 4710342 | J46: 60000 | K46: =I46*J46 -> 282620520000 | L46: 183943 | M46: 60000 | N46: =L46*M46 -> 11036580000 | O46: =N46/K46 -> 0.03905088
D47: b. | E47: Kendaraan Bermotor Roda 4 atau lebih | I47: 1289658 | J47: 100000 | K47: =I47*J47 -> 128965800000 | L47: 40525 | M47: 100000 | N47: =L47*M47 -> 4052500000 | O47: =N47/K47 -> 0.031423059
C49: 6 | D49: Penerbitan Surat Tanda Coba Kendaraan Bermotor (STCK) | I49: 1500000 | K49: =SUM(K50:K51) -> 43861750000 | L49: =SUM(L50:L51) -> 52281 | N49: =SUM(N50:N51) -> 1454650000 | O49: =N49/K49 -> 0.033164431
D50: a. | E50: Kendaraan Bermotor Roda 2 atau 3 | I50: 1245530 | J50: 25000 | K50: =I50*J50 -> 31138250000 | L50: 46376 | M50: 25000 | N50: =L50*M50 -> 1159400000 | O50: =N50/K50 -> 0.037233949
D51: b. | E51: Kendaraan Bermotor Roda 4 atau lebih | I51: 254470 | J51: 50000 | K51: =I51*J51 -> 12723500000 | L51: 5905 | M51: 50000 | N51: =L51*M51 -> 295250000 | O51: =N51/K51 -> 0.023205093
C53: 7 | D53: Penerbitan Tanda Coba Kendaraan Bermotor (TCKB) | I53: 75000 | K53: =SUM(K54:K55) -> 5024800000 | L53: =SUM(L54:L55) -> 4260 | N53: =SUM(N54:N55) -> 299120000 | O53: =N53/K53 -> 0.059528737
...

Sheet JUNI
B6: REALISASI TARGET PNBP T.A. 2026
B7: BULAN JUNI T.A. 2026
B10: NO | C10: JENIS PENERIMAAN | I10: DATA TARGET | L10: REALISASI | O10: PROSENTASE
I11: VOLUME | J11: TARIF | K11: TARGET (Rp.) | L11: VOLUME | M11: TARIF | N11: REALISASI (Rp.)
B12: 1 | C12: 2 | I12: 3 | J12: 4 | K12: 5 | L12: 3 | M12: 4 | N12: 5 | O12: 6
C13: 1 | D13: Pengujian untuk penerbitan Surat Izin Mengemudi (SIM) baru | I13: 1002980 | K13: =SUM(K14:K22) -> 106956030000 | L13: =SUM(L14:L22) -> 40913 | N13: =SUM(N14:N22) -> 4402220000 | O13: =N13/K13 -> 0.041159157
D14: a. | E14: Penerbitan SIM A | I14: 294130 | J14: 120000 | K14: =I14*J14 -> 35295600000 | L14: 13575 | M14: 120000 | N14: =L14*M14 -> 1629000000 | O14: =N14/K14 -> 0.046153062
D15: b. | E15: Penerbitan SIM B I | I15: 30304 | J15: 120000 | K15: =I15*J15 -> 3636480000 | L15: 1505 | M15: 120000 | N15: =L15*M15 -> 180600000 | O15: =N15/K15 -> 0.049663411
D16: c. | E16: Penerbitan SIM B II | I16: 13370 | J16: 120000 | K16: =I16*J16 -> 1604400000 | L16: 491 | M16: 120000 | N16: =L16*M16 -> 58920000 | O16: =N16/K16 -> 0.036724009
D17: d. | E17: Penerbitan SIM C | I17: 662649 | J17: 100000 | K17: =I17*J17 -> 66264900000 | L17: 25327 | M17: 100000 | N17: =L17*M17 -> 2532700000 | O17: =N17/K17 -> 0.038220838
D18: e. | E18: Penerbitan SIM C I | I18: 299 | J18: 100000 | K18: =I18*J18 -> 29900000 | L18: 5 | M18: 100000 | N18: =L18*M18 -> 500000 | O18: =N18/K18 -> 0.016722408
D19: f. | E19: Penerbitan SIM C II | I19: 267 | J19: 100000 | K19: =I19*J19 -> 26700000 | L19: 0 | M19: 100000 | N19: =L19*M19 -> 0 | O19: =N19/K19 -> 0
D20: g. | E20: Penerbitan SIM D | I20: 1925 | J20: 50000 | K20: =I20*J20 -> 96250000 | L20: 9 | M20: 50000 | N20: =L20*M20 -> 450000 | O20: =N20/K20 -> 0.0046753247
D21: h. | E21: Penerbitan SIM D I | I21: 36 | J21: 50000 | K21: =I21*J21 -> 1800000 | L21: 1 | M21: 50000 | N21: =L21*M21 -> 50000 | O21: =N21/K21 -> 0.027777778
D22: i. | E22: Pembuatan SIM International | I22: 0 | J22: 250000 | K22: =I22*J22 -> 0 | L22: 0 | M22: 250000 | N22: =L22*M22 -> 0 | O22: =N22/K22 -> #DIV/0!
C24: 2 | D24: Penerbitan Perpanjangan Surat Izin Mengemudi (SIM) | I24: 1997021 | K24: =SUM(K25:K33) -> 153240870000 | L24: =SUM(L25:L33) -> 140080 | N24: =SUM(N25:N33) -> 10739465000 | O24: =N24/K24 -> 0.07008225
D25: a. | E25: Penerbitan SIM A | I25: 596792 | J25: 80000 | K25: =I25*J25 -> 47743360000 | L25: 41758 | M25: 80000 | N25: =L25*M25 -> 3340640000 | O25: =N25/K25 -> 0.069970777
D26: b. | E26: Penerbitan SIM B I | I26: 63576 | J26: 80000 | K26: =I26*J26 -> 5086080000 | L26: 3147 | M26: 80000 | N26: =L26*M26 -> 251760000 | O26: =N26/K26 -> 0.049499811
D27: c. | E27: Penerbitan SIM B II | I27: 35983 | J27: 80000 | K27: =I27*J27 -> 2878640000 | L27: 1986 | M27: 80000 | N27: =L27*M27 -> 158880000 | O27: =N27/K27 -> 0.05519273
D28: d. | E28: Penerbitan SIM C | I28: 1296381 | J28: 75000 | K28: =I28*J28 -> 97228575000 | L28: 93165 | M28: 75000 | N28: =L28*M28 -> 6987375000 | O28: =N28/K28 -> 0.071865447
D29: e. | E29: Penerbitan SIM C I | I29: 3815 | J29: 75000 | K29: =I29*J29 -> 286125000 | L29: 0 | M29: 75000 | N29: =L29*M29 -> 0 | O29: =N29/K29 -> 0
D30: f. | E30: Penerbitan SIM C II | I30: 86 | J30: 75000 | K30: =I30*J30 -> 6450000 | L30: 2 | M30: 75000 | N30: =L30*M30 -> 150000 | O30: =N30/K30 -> 0.023255814
D31: g. | E31: Penerbitan SIM D | I31: 360 | J31: 30000 | K31: =I31*J31 -> 10800000 | L31: 22 | M31: 30000 | N31: =L31*M31 -> 660000 | O31: =N31/K31 -> 0.061111111
D32: h. | E32: Penerbitan SIM D I | I32: 28 | J32: 30000 | K32: =I32*J32 -> 840000 | L32: 0 | M32: 30000 | N32: =L32*M32 -> 0 | O32: =N32/K32 -> 0
D33: i. | E33: Penerbitan SIM Internasional | I33: 0 | J33: 225000 | K33: =I33*J33 -> 0 | L33: 0 | M33: 225000 | N33: =L33*M33 -> 0
C35: 3 | D35: Penerbitan Surat Keterangan Uji Keterampilan Pengemudi (SKUKP) | I35: 100000 | J35: 50000 | K35: =I35*J35 -> 5000000000 | L35: 7337 | M35: 50000 | N35: =L35*M35 -> 366850000 | O35: =N35/K35 -> 0.07337
C37: 4 | D37: Penerbitan Surat Tanda Nomor Kendaraan Bermotor (STNK) | I37: 6000000 | K37: =+K38+K41 -> 727309900000 | L37: =L38+L41 -> 271321 | N37: =+N38+N41 -> 32009900000 | O37: =N37/K37 -> 0.044011363
D38: a. | E38: Kendaraan Bermotor roda 2 atau roda 3 | I38: 4726901 | K38: =SUM(K39:K40) -> 472690100000 | L38: =SUM(L39:L40) -> 222543 | N38: =SUM(N39:N40) -> 22254300000 | O38: =N38/K38 -> 0.047080106
E39: 1) | F39: Baru | I39: 2267860 | J39: 100000 | K39: =I39*J39 -> 226786000000 | L39: 54025 | M39: 100000 | N39: =L39*M39 -> 5402500000 | O39: =N39/K39 -> 0.023822017
E40: 2) | F40: Perpanjangan | I40: 2459041 | J40: 100000 | K40: =I40*J40 -> 245904100000 | L40: 168518 | M40: 100000 | N40: =L40*M40 -> 16851800000 | O40: =N40/K40 -> 0.068529968
D41: b. | E41: Kendaraan bermotor roda 4 atau lebih | I41: 1273099 | K41: =SUM(K42:K43) -> 254619800000 | L41: =SUM(L42:L43) -> 48778 | N41: =SUM(N42:N43) -> 9755600000 | O41: =N41/K41 -> 0.038314381
E42: 1) | F42: Baru | I42: 626781 | J42: 200000 | K42: =I42*J42 -> 125356200000 | L42: 6333 | M42: 200000 | N42: =L42*M42 -> 1266600000 | O42: =N42/K42 -> 0.010104008
E43: 2) | F43: Perpanjangan | I43: 646318 | J43: 200000 | K43: =I43*J43 -> 129263600000 | L43: 42445 | M43: 200000 | N43: =L43*M43 -> 8489000000 | O43: =N43/K43 -> 0.065672007
C45: 5 | D45: Penerbitan Tanda Nomor Kendaraan Bermotor (TNKB) | I45: 6000000 | K45: =SUM(K46,K47) -> 411586320000 | L45: =SUM(L46:L47) -> 265695 | N45: =SUM(N46,N47) -> 17866420000 | O45: =N45/K45 -> 0.043408683
D46: a. | E46: Kendaraan Bermotor Roda 2 atau 3 | I46: 4710342 | J46: 60000 | K46: =I46*J46 -> 282620520000 | L46: 217577 | M46: 60000 | N46: =L46*M46 -> 13054620000 | O46: =N46/K46 -> 0.046191338
D47: b. | E47: Kendaraan Bermotor Roda 4 atau lebih | I47: 1289658 | J47: 100000 | K47: =I47*J47 -> 128965800000 | L47: 48118 | M47: 100000 | N47: =L47*M47 -> 4811800000 | O47: =N47/K47 -> 0.037310667
C49: 6 | D49: Penerbitan Surat Tanda Coba Kendaraan Bermotor (STCK) | I49: 1500000 | K49: =SUM(K50:K51) -> 43861750000 | L49: =SUM(L50:L51) -> 60902 | N49: =SUM(N50:N51) -> 1697725000 | O49: =N49/K49 -> 0.038706276
D50: a. | E50: Kendaraan Bermotor Roda 2 atau 3 | I50: 1245530 | J50: 25000 | K50: =I50*J50 -> 31138250000 | L50: 53895 | M50: 25000 | N50: =L50*M50 -> 1347375000 | O50: =N50/K50 -> 0.043270736
D51: b. | E51: Kendaraan Bermotor Roda 4 atau lebih | I51: 254470 | J51: 50000 | K51: =I51*J51 -> 12723500000 | L51: 7007 | M51: 50000 | N51: =L51*M51 -> 350350000 | O51: =N51/K51 -> 0.027535662
C53: 7 | D53: Penerbitan Tanda Coba Kendaraan Bermotor (TCKB) | I53: 75000 | K53: =SUM(K54:K55) -> 5024800000 | L53: =SUM(L54:L55) -> 4904 | N53: =SUM(N54:N55) -> 344080000 | O53: =N53/K53 -> 0.068476357
...

Sheet JULI
B6: REALISASI TARGET PNBP T.A. 2026
B7: BULAN JULI T.A. 2026
B10: NO | C10: JENIS PENERIMAAN | I10: DATA TARGET | L10: REALISASI | O10: PROSENTASE
I11: VOLUME | J11: TARIF | K11: TARGET (Rp.) | L11: VOLUME | M11: TARIF | N11: REALISASI (Rp.)
B12: 1 | C12: 2 | I12: 3 | J12: 4 | K12: 5 | L12: 3 | M12: 4 | N12: 5 | O12: 6
C13: 1 | D13: Pengujian untuk penerbitan Surat Izin Mengemudi (SIM) baru | I13: 1002980 | K13: =SUM(K14:K22) -> 106956030000 | L13: =SUM(L14:L22) -> 45662 | N13: =SUM(N14:N22) -> 4888410000 | O13: =N13/K13 -> 0.045704856
D14: a. | E14: Penerbitan SIM A | I14: 294130 | J14: 120000 | K14: =I14*J14 -> 35295600000 | L14: 14055 | M14: 120000 | N14: =L14*M14 -> 1686600000 | O14: =N14/K14 -> 0.047784993
D15: b. | E15: Penerbitan SIM B I | I15: 30304 | J15: 120000 | K15: =I15*J15 -> 3636480000 | L15: 1516 | M15: 120000 | N15: =L15*M15 -> 181920000 | O15: =N15/K15 -> 0.050026399
D16: c. | E16: Penerbitan SIM B II | I16: 13370 | J16: 120000 | K16: =I16*J16 -> 1604400000 | L16: 552 | M16: 120000 | N16: =L16*M16 -> 66240000 | O16: =N16/K16 -> 0.041286462
D17: d. | E17: Penerbitan SIM C | I17: 662649 | J17: 100000 | K17: =I17*J17 -> 66264900000 | L17: 29527 | M17: 100000 | N17: =L17*M17 -> 2952700000 | O17: =N17/K17 -> 0.044559035
D18: e. | E18: Penerbitan SIM C I | I18: 299 | J18: 100000 | K18: =I18*J18 -> 29900000 | L18: 7 | M18: 100000 | N18: =L18*M18 -> 700000 | O18: =N18/K18 -> 0.023411371
D19: f. | E19: Penerbitan SIM C II | I19: 267 | J19: 100000 | K19: =I19*J19 -> 26700000 | L19: 0 | M19: 100000 | N19: =L19*M19 -> 0 | O19: =N19/K19 -> 0
D20: g. | E20: Penerbitan SIM D | I20: 1925 | J20: 50000 | K20: =I20*J20 -> 96250000 | L20: 5 | M20: 50000 | N20: =L20*M20 -> 250000 | O20: =N20/K20 -> 0.0025974026
D21: h. | E21: Penerbitan SIM D I | I21: 36 | J21: 50000 | K21: =I21*J21 -> 1800000 | L21: 0 | M21: 50000 | N21: =L21*M21 -> 0 | O21: =N21/K21 -> 0
D22: i. | E22: Pembuatan SIM International | I22: 0 | J22: 250000 | K22: =I22*J22 -> 0 | L22: 0 | M22: 250000 | N22: =L22*M22 -> 0 | O22: =N22/K22 -> #DIV/0!
C24: 2 | D24: Penerbitan Perpanjangan Surat Izin Mengemudi (SIM) | I24: 1997021 | K24: =SUM(K25:K33) -> 153240870000 | L24: =SUM(L25:L33) -> 113312 | N24: =SUM(N25:N33) -> 8686150000 | O24: =N24/K24 -> 0.056682985
D25: a. | E25: Penerbitan SIM A | I25: 596792 | J25: 80000 | K25: =I25*J25 -> 47743360000 | L25: 33650 | M25: 80000 | N25: =L25*M25 -> 2692000000 | O25: =N25/K25 -> 0.056384804
D26: b. | E26: Penerbitan SIM B I | I26: 63576 | J26: 80000 | K26: =I26*J26 -> 5086080000 | L26: 2448 | M26: 80000 | N26: =L26*M26 -> 195840000 | O26: =N26/K26 -> 0.038505096
D27: c. | E27: Penerbitan SIM B II | I27: 35983 | J27: 80000 | K27: =I27*J27 -> 2878640000 | L27: 1560 | M27: 80000 | N27: =L27*M27 -> 124800000 | O27: =N27/K27 -> 0.043353806
D28: d. | E28: Penerbitan SIM C | I28: 1296381 | J28: 75000 | K28: =I28*J28 -> 97228575000 | L28: 75642 | M28: 75000 | N28: =L28*M28 -> 5673150000 | O28: =N28/K28 -> 0.058348587
D29: e. | E29: Penerbitan SIM C I | I29: 3815 | J29: 75000 | K29: =I29*J29 -> 286125000 | L29: 0 | M29: 75000 | N29: =L29*M29 -> 0 | O29: =N29/K29 -> 0
D30: f. | E30: Penerbitan SIM C II | I30: 86 | J30: 75000 | K30: =I30*J30 -> 6450000 | L30: 0 | M30: 75000 | N30: =L30*M30 -> 0 | O30: =N30/K30 -> 0
D31: g. | E31: Penerbitan SIM D | I31: 360 | J31: 30000 | K31: =I31*J31 -> 10800000 | L31: 12 | M31: 30000 | N31: =L31*M31 -> 360000 | O31: =N31/K31 -> 0.033333333
D32: h. | E32: Penerbitan SIM D I | I32: 28 | J32: 30000 | K32: =I32*J32 -> 840000 | L32: 0 | M32: 30000 | N32: =L32*M32 -> 0 | O32: =N32/K32 -> 0
D33: i. | E33: Penerbitan SIM Internasional | I33: 0 | J33: 225000 | K33: =I33*J33 -> 0 | L33: 0 | M33: 225000 | N33: =L33*M33 -> 0
C35: 3 | D35: Penerbitan Surat Keterangan Uji Keterampilan Pengemudi (SKUKP) | I35: 100000 | J35: 50000 | K35: =I35*J35 -> 5000000000 | L35: 6810 | M35: 50000 | N35: =L35*M35 -> 340500000 | O35: =N35/K35 -> 0.0681
C37: 4 | D37: Penerbitan Surat Tanda Nomor Kendaraan Bermotor (STNK) | I37: 6000000 | K37: =+K38+K41 -> 727309900000 | L37: =L38+L41 -> 254870 | N37: =+N38+N41 -> 29720400000 | O37: =N37/K37 -> 0.040863461
D38: a. | E38: Kendaraan Bermotor roda 2 atau roda 3 | I38: 4726901 | K38: =SUM(K39:K40) -> 472690100000 | L38: =SUM(L39:L40) -> 212536 | N38: =SUM(N39:N40) -> 21253600000 | O38: =N38/K38 -> 0.044963074
E39: 1) | F39: Baru | I39: 2267860 | J39: 100000 | K39: =I39*J39 -> 226786000000 | L39: 56885 | M39: 100000 | N39: =L39*M39 -> 5688500000 | O39: =N39/K39 -> 0.025083118
E40: 2) | F40: Perpanjangan | I40: 2459041 | J40: 100000 | K40: =I40*J40 -> 245904100000 | L40: 155651 | M40: 100000 | N40: =L40*M40 -> 15565100000 | O40: =N40/K40 -> 0.06329744
D41: b. | E41: Kendaraan bermotor roda 4 atau lebih | I41: 1273099 | K41: =SUM(K42:K43) -> 254619800000 | L41: =SUM(L42:L43) -> 42334 | N41: =SUM(N42:N43) -> 8466800000 | O41: =N41/K41 -> 0.033252716
E42: 1) | F42: Baru | I42: 626781 | J42: 200000 | K42: =I42*J42 -> 125356200000 | L42: 6330 | M42: 200000 | N42: =L42*M42 -> 1266000000 | O42: =N42/K42 -> 0.010099221
E43: 2) | F43: Perpanjangan | I43: 646318 | J43: 200000 | K43: =I43*J43 -> 129263600000 | L43: 36004 | M43: 200000 | N43: =L43*M43 -> 7200800000 | O43: =N43/K43 -> 0.055706324
C45: 5 | D45: Penerbitan Tanda Nomor Kendaraan Bermotor (TNKB) | I45: 6000000 | K45: =SUM(K46,K47) -> 411586320000 | L45: =SUM(L46:L47) -> 248328 | N45: =SUM(N46,N47) -> 16565760000 | O45: =N45/K45 -> 0.040248568
D46: a. | E46: Kendaraan Bermotor Roda 2 atau 3 | I46: 4710342 | J46: 60000 | K46: =I46*J46 -> 282620520000 | L46: 206676 | M46: 60000 | N46: =L46*M46 -> 12400560000 | O46: =N46/K46 -> 0.043877069
D47: b. | E47: Kendaraan Bermotor Roda 4 atau lebih | I47: 1289658 | J47: 100000 | K47: =I47*J47 -> 128965800000 | L47: 41652 | M47: 100000 | N47: =L47*M47 -> 4165200000 | O47: =N47/K47 -> 0.032296935
C49: 6 | D49: Penerbitan Surat Tanda Coba Kendaraan Bermotor (STCK) | I49: 1500000 | K49: =SUM(K50:K51) -> 43861750000 | L49: =SUM(L50:L51) -> 63495 | N49: =SUM(N50:N51) -> 1749475000 | O49: =N49/K49 -> 0.039886119
D50: a. | E50: Kendaraan Bermotor Roda 2 atau 3 | I50: 1245530 | J50: 25000 | K50: =I50*J50 -> 31138250000 | L50: 57011 | M50: 25000 | N50: =L50*M50 -> 1425275000 | O50: =N50/K50 -> 0.045772482
D51: b. | E51: Kendaraan Bermotor Roda 4 atau lebih | I51: 254470 | J51: 50000 | K51: =I51*J51 -> 12723500000 | L51: 6484 | M51: 50000 | N51: =L51*M51 -> 324200000 | O51: =N51/K51 -> 0.02548041
C53: 7 | D53: Penerbitan Tanda Coba Kendaraan Bermotor (TCKB) | I53: 75000 | K53: =SUM(K54:K55) -> 5024800000 | L53: =SUM(L54:L55) -> 5243 | N53: =SUM(N54:N55) -> 364540000 | O53: =N53/K53 -> 0.072548161
...

Sheet AGUSTUS
B6: REALISASI TARGET PNBP T.A. 2026
B7: BULAN AGUSTUS T.A. 2026
B10: NO | C10: JENIS PENERIMAAN | I10: DATA TARGET | L10: REALISASI | O10: PROSENTASE
I11: VOLUME | J11: TARIF | K11: TARGET (Rp.) | L11: VOLUME | M11: TARIF | N11: REALISASI (Rp.)
B12: 1 | C12: 2 | I12: 3 | J12: 4 | K12: 5 | L12: 3 | M12: 4 | N12: 5 | O12: 6
C13: 1 | D13: Pengujian untuk penerbitan Surat Izin Mengemudi (SIM) baru | I13: 1002980 | K13: =SUM(K14:K22) -> 106956030000 | L13: =SUM(L14:L22) -> 33908 | N13: =SUM(N14:N22) -> 3654190000 | O13: =N13/K13 -> 0.034165348
D14: a. | E14: Penerbitan SIM A | I14: 294130 | J14: 120000 | K14: =I14*J14 -> 35295600000 | L14: 11358 | M14: 120000 | N14: =L14*M14 -> 1362960000 | O14: =N14/K14 -> 0.038615578
D15: b. | E15: Penerbitan SIM B I | I15: 30304 | J15: 120000 | K15: =I15*J15 -> 3636480000 | L15: 1318 | M15: 120000 | N15: =L15*M15 -> 158160000 | O15: =N15/K15 -> 0.043492608
D16: c. | E16: Penerbitan SIM B II | I16: 13370 | J16: 120000 | K16: =I16*J16 -> 1604400000 | L16: 511 | M16: 120000 | N16: =L16*M16 -> 61320000 | O16: =N16/K16 -> 0.038219895
D17: d. | E17: Penerbitan SIM C | I17: 662649 | J17: 100000 | K17: =I17*J17 -> 66264900000 | L17: 20711 | M17: 100000 | N17: =L17*M17 -> 2071100000 | O17: =N17/K17 -> 0.031254857
D18: e. | E18: Penerbitan SIM C I | I18: 299 | J18: 100000 | K18: =I18*J18 -> 29900000 | L18: 3 | M18: 100000 | N18: =L18*M18 -> 300000 | O18: =N18/K18 -> 0.010033445
D19: f. | E19: Penerbitan SIM C II | I19: 267 | J19: 100000 | K19: =I19*J19 -> 26700000 | L19: 0 | M19: 100000 | N19: =L19*M19 -> 0 | O19: =N19/K19 -> 0
D20: g. | E20: Penerbitan SIM D | I20: 1925 | J20: 50000 | K20: =I20*J20 -> 96250000 | L20: 6 | M20: 50000 | N20: =L20*M20 -> 300000 | O20: =N20/K20 -> 0.0031168831
D21: h. | E21: Penerbitan SIM D I | I21: 36 | J21: 50000 | K21: =I21*J21 -> 1800000 | L21: 1 | M21: 50000 | N21: =L21*M21 -> 50000 | O21: =N21/K21 -> 0.027777778
D22: i. | E22: Pembuatan SIM International | I22: 0 | J22: 250000 | K22: =I22*J22 -> 0 | L22: 0 | M22: 250000 | N22: =L22*M22 -> 0 | O22: =N22/K22 -> #DIV/0!
C24: 2 | D24: Penerbitan Perpanjangan Surat Izin Mengemudi (SIM) | I24: 1997021 | K24: =SUM(K25:K33) -> 153240870000 | L24: =SUM(L25:L33) -> 108424 | N24: =SUM(N25:N33) -> 8315665000 | O24: =N24/K24 -> 0.054265321
D25: a. | E25: Penerbitan SIM A | I25: 596792 | J25: 80000 | K25: =I25*J25 -> 47743360000 | L25: 32618 | M25: 80000 | N25: =L25*M25 -> 2609440000 | O25: =N25/K25 -> 0.054655558
D26: b. | E26: Penerbitan SIM B I | I26: 63576 | J26: 80000 | K26: =I26*J26 -> 5086080000 | L26: 2615 | M26: 80000 | N26: =L26*M26 -> 209200000 | O26: =N26/K26 -> 0.041131874
D27: c. | E27: Penerbitan SIM B II | I27: 35983 | J27: 80000 | K27: =I27*J27 -> 2878640000 | L27: 1612 | M27: 80000 | N27: =L27*M27 -> 128960000 | O27: =N27/K27 -> 0.044798933
D28: d. | E28: Penerbitan SIM C | I28: 1296381 | J28: 75000 | K28: =I28*J28 -> 97228575000 | L28: 71571 | M28: 75000 | N28: =L28*M28 -> 5367825000 | O28: =N28/K28 -> 0.055208307
D29: e. | E29: Penerbitan SIM C I | I29: 3815 | J29: 75000 | K29: =I29*J29 -> 286125000 | L29: 0 | M29: 75000 | N29: =L29*M29 -> 0 | O29: =N29/K29 -> 0
D30: f. | E30: Penerbitan SIM C II | I30: 86 | J30: 75000 | K30: =I30*J30 -> 6450000 | L30: 0 | M30: 75000 | N30: =L30*M30 -> 0 | O30: =N30/K30 -> 0
D31: g. | E31: Penerbitan SIM D | I31: 360 | J31: 30000 | K31: =I31*J31 -> 10800000 | L31: 8 | M31: 30000 | N31: =L31*M31 -> 240000 | O31: =N31/K31 -> 0.022222222
D32: h. | E32: Penerbitan SIM D I | I32: 28 | J32: 30000 | K32: =I32*J32 -> 840000 | L32: 0 | M32: 30000 | N32: =L32*M32 -> 0 | O32: =N32/K32 -> 0
D33: i. | E33: Penerbitan SIM Internasional | I33: 0 | J33: 225000 | K33: =I33*J33 -> 0 | L33: 0 | M33: 225000 | N33: =L33*M33 -> 0
C35: 3 | D35: Penerbitan Surat Keterangan Uji Keterampilan Pengemudi (SKUKP) | I35: 100000 | J35: 50000 | K35: =I35*J35 -> 5000000000 | L35: 5941 | M35: 50000 | N35: =L35*M35 -> 297050000 | O35: =N35/K35 -> 0.05941
C37: 4 | D37: Penerbitan Surat Tanda Nomor Kendaraan Bermotor (STNK) | I37: 6000000 | K37: =+K38+K41 -> 727309900000 | L37: =L38+L41 -> 279047 | N37: =+N38+N41 -> 32410500000 | O37: =N37/K37 -> 0.04456216
D38: a. | E38: Kendaraan Bermotor roda 2 atau roda 3 | I38: 4726901 | K38: =SUM(K39:K40) -> 472690100000 | L38: =SUM(L39:L40) -> 233989 | N38: =SUM(N39:N40) -> 23398900000 | O38: =N38/K38 -> 0.049501566
E39: 1) | F39: Baru | I39: 2267860 | J39: 100000 | K39: =I39*J39 -> 226786000000 | L39: 52453 | M39: 100000 | N39: =L39*M39 -> 5245300000 | O39: =N39/K39 -> 0.023128853
E40: 2) | F40: Perpanjangan | I40: 2459041 | J40: 100000 | K40: =I40*J40 -> 245904100000 | L40: 181536 | M40: 100000 | N40: =L40*M40 -> 18153600000 | O40: =N40/K40 -> 0.073823901
D41: b. | E41: Kendaraan bermotor roda 4 atau lebih | I41: 1273099 | K41: =SUM(K42:K43) -> 254619800000 | L41: =SUM(L42:L43) -> 45058 | N41: =SUM(N42:N43) -> 9011600000 | O41: =N41/K41 -> 0.035392377
E42: 1) | F42: Baru | I42: 626781 | J42: 200000 | K42: =I42*J42 -> 125356200000 | L42: 5268 | M42: 200000 | N42: =L42*M42 -> 1053600000 | O42: =N42/K42 -> 0.0084048495
E43: 2) | F43: Perpanjangan | I43: 646318 | J43: 200000 | K43: =I43*J43 -> 129263600000 | L43: 39790 | M43: 200000 | N43: =L43*M43 -> 7958000000 | O43: =N43/K43 -> 0.061564122
C45: 5 | D45: Penerbitan Tanda Nomor Kendaraan Bermotor (TNKB) | I45: 6000000 | K45: =SUM(K46,K47) -> 411586320000 | L45: =SUM(L46:L47) -> 273117 | N45: =SUM(N46,N47) -> 18163260000 | O45: =N45/K45 -> 0.044129892
D46: a. | E46: Kendaraan Bermotor Roda 2 atau 3 | I46: 4710342 | J46: 60000 | K46: =I46*J46 -> 282620520000 | L46: 228711 | M46: 60000 | N46: =L46*M46 -> 13722660000 | O46: =N46/K46 -> 0.048555073
D47: b. | E47: Kendaraan Bermotor Roda 4 atau lebih | I47: 1289658 | J47: 100000 | K47: =I47*J47 -> 128965800000 | L47: 44406 | M47: 100000 | N47: =L47*M47 -> 4440600000 | O47: =N47/K47 -> 0.034432384
C49: 6 | D49: Penerbitan Surat Tanda Coba Kendaraan Bermotor (STCK) | I49: 1500000 | K49: =SUM(K50:K51) -> 43861750000 | L49: =SUM(L50:L51) -> 58133 | N49: =SUM(N50:N51) -> 1594200000 | O49: =N49/K49 -> 0.036346019
D50: a. | E50: Kendaraan Bermotor Roda 2 atau 3 | I50: 1245530 | J50: 25000 | K50: =I50*J50 -> 31138250000 | L50: 52498 | M50: 25000 | N50: =L50*M50 -> 1312450000 | O50: =N50/K50 -> 0.042149125
D51: b. | E51: Kendaraan Bermotor Roda 4 atau lebih | I51: 254470 | J51: 50000 | K51: =I51*J51 -> 12723500000 | L51: 5635 | M51: 50000 | N51: =L51*M51 -> 281750000 | O51: =N51/K51 -> 0.022144064
C53: 7 | D53: Penerbitan Tanda Coba Kendaraan Bermotor (TCKB) | I53: 75000 | K53: =SUM(K54:K55) -> 5024800000 | L53: =SUM(L54:L55) -> 4659 | N53: =SUM(N54:N55) -> 323060000 | O53: =N53/K53 -> 0.064293106
...

Sheet SEPT
B6: REALISASI TARGET PNBP T.A. 2026
B7: BULAN SEPTEMBER T.A. 2026
B10: NO | C10: JENIS PENERIMAAN | I10: DATA TARGET | L10: REALISASI | O10: PROSENTASE
I11: VOLUME | J11: TARIF | K11: TARGET (Rp.) | L11: VOLUME | M11: TARIF | N11: REALISASI (Rp.)
B12: 1 | C12: 2 | I12: 3 | J12: 4 | K12: 5 | L12: 3 | M12: 4 | N12: 5 | O12: 6
C13: 1 | D13: Pengujian untuk penerbitan Surat Izin Mengemudi (SIM) baru | I13: 1002980 | K13: =SUM(K14:K22) -> 106956030000 | L13: =SUM(L14:L22) -> 31199 | N13: =SUM(N14:N22) -> 3378890000 | O13: =N13/K13 -> 0.031591393
D14: a. | E14: Penerbitan SIM A | I14: 294130 | J14: 120000 | K14: =I14*J14 -> 35295600000 | L14: 11098 | M14: 120000 | N14: =L14*M14 -> 1331760000 | O14: =N14/K14 -> 0.037731615
D15: b. | E15: Penerbitan SIM B I | I15: 30304 | J15: 120000 | K15: =I15*J15 -> 3636480000 | L15: 1341 | M15: 120000 | N15: =L15*M15 -> 160920000 | O15: =N15/K15 -> 0.044251584
D16: c. | E16: Penerbitan SIM B II | I16: 13370 | J16: 120000 | K16: =I16*J16 -> 1604400000 | L16: 518 | M16: 120000 | N16: =L16*M16 -> 62160000 | O16: =N16/K16 -> 0.038743455
D17: d. | E17: Penerbitan SIM C | I17: 662649 | J17: 100000 | K17: =I17*J17 -> 66264900000 | L17: 18237 | M17: 100000 | N17: =L17*M17 -> 1823700000 | O17: =N17/K17 -> 0.027521357
D18: e. | E18: Penerbitan SIM C I | I18: 299 | J18: 100000 | K18: =I18*J18 -> 29900000 | L18: 2 | M18: 100000 | N18: =L18*M18 -> 200000 | O18: =N18/K18 -> 0.0066889632
D19: f. | E19: Penerbitan SIM C II | I19: 267 | J19: 100000 | K19: =I19*J19 -> 26700000 | L19: 0 | M19: 100000 | N19: =L19*M19 -> 0 | O19: =N19/K19 -> 0
D20: g. | E20: Penerbitan SIM D | I20: 1925 | J20: 50000 | K20: =I20*J20 -> 96250000 | L20: 3 | M20: 50000 | N20: =L20*M20 -> 150000 | O20: =N20/K20 -> 0.0015584416
D21: h. | E21: Penerbitan SIM D I | I21: 36 | J21: 50000 | K21: =I21*J21 -> 1800000 | L21: 0 | M21: 50000 | N21: =L21*M21 -> 0 | O21: =N21/K21 -> 0
D22: i. | E22: Pembuatan SIM International | I22: 0 | J22: 250000 | K22: =I22*J22 -> 0 | L22: 0 | M22: 250000 | N22: =L22*M22 -> 0 | O22: =N22/K22 -> #DIV/0!
C24: 2 | D24: Penerbitan Perpanjangan Surat Izin Mengemudi (SIM) | I24: 1997021 | K24: =SUM(K25:K33) -> 153240870000 | L24: =SUM(L25:L33) -> 97825 | N24: =SUM(N25:N33) -> 7505130000 | O24: =N24/K24 -> 0.048976034
D25: a. | E25: Penerbitan SIM A | I25: 596792 | J25: 80000 | K25: =I25*J25 -> 47743360000 | L25: 30219 | M25: 80000 | N25: =L25*M25 -> 2417520000 | O25: =N25/K25 -> 0.050635732
D26: b. | E26: Penerbitan SIM B I | I26: 63576 | J26: 80000 | K26: =I26*J26 -> 5086080000 | L26: 2172 | M26: 80000 | N26: =L26*M26 -> 173760000 | O26: =N26/K26 -> 0.034163835
D27: c. | E27: Penerbitan SIM B II | I27: 35983 | J27: 80000 | K27: =I27*J27 -> 2878640000 | L27: 1332 | M27: 80000 | N27: =L27*M27 -> 106560000 | O27: =N27/K27 -> 0.03701748
D28: d. | E28: Penerbitan SIM C | I28: 1296381 | J28: 75000 | K28: =I28*J28 -> 97228575000 | L28: 64094 | M28: 75000 | N28: =L28*M28 -> 4807050000 | O28: =N28/K28 -> 0.049440712
D29: e. | E29: Penerbitan SIM C I | I29: 3815 | J29: 75000 | K29: =I29*J29 -> 286125000 | L29: 0 | M29: 75000 | N29: =L29*M29 -> 0 | O29: =N29/K29 -> 0
D30: f. | E30: Penerbitan SIM C II | I30: 86 | J30: 75000 | K30: =I30*J30 -> 6450000 | L30: 0 | M30: 75000 | N30: =L30*M30 -> 0 | O30: =N30/K30 -> 0
D31: g. | E31: Penerbitan SIM D | I31: 360 | J31: 30000 | K31: =I31*J31 -> 10800000 | L31: 8 | M31: 30000 | N31: =L31*M31 -> 240000 | O31: =N31/K31 -> 0.022222222
D32: h. | E32: Penerbitan SIM D I | I32: 28 | J32: 30000 | K32: =I32*J32 -> 840000 | L32: 0 | M32: 30000 | N32: =L32*M32 -> 0 | O32: =N32/K32 -> 0
D33: i. | E33: Penerbitan SIM Internasional | I33: 0 | J33: 225000 | K33: =I33*J33 -> 0 | L33: 0 | M33: 225000 | N33: =L33*M33 -> 0
C35: 3 | D35: Penerbitan Surat Keterangan Uji Keterampilan Pengemudi (SKUKP) | I35: 100000 | J35: 50000 | K35: =I35*J35 -> 5000000000 | L35: 5501 | M35: 50000 | N35: =L35*M35 -> 275050000 | O35: =N35/K35 -> 0.05501
C37: 4 | D37: Penerbitan Surat Tanda Nomor Kendaraan Bermotor (STNK) | I37: 6000000 | K37: =+K38+K41 -> 727309900000 | L37: =L38+L41 -> 272578 | N37: =+N38+N41 -> 31986000000 | O37: =N37/K37 -> 0.043978502
D38: a. | E38: Kendaraan Bermotor roda 2 atau roda 3 | I38: 4726901 | K38: =SUM(K39:K40) -> 472690100000 | L38: =SUM(L39:L40) -> 225296 | N38: =SUM(N39:N40) -> 22529600000 | O38: =N38/K38 -> 0.047662517
E39: 1) | F39: Baru | I39: 2267860 | J39: 100000 | K39: =I39*J39 -> 226786000000 | L39: 55867 | M39: 100000 | N39: =L39*M39 -> 5586700000 | O39: =N39/K39 -> 0.024634237
E40: 2) | F40: Perpanjangan | I40: 2459041 | J40: 100000 | K40: =I40*J40 -> 245904100000 | L40: 169429 | M40: 100000 | N40: =L40*M40 -> 16942900000 | O40: =N40/K40 -> 0.068900437
D41: b. | E41: Kendaraan bermotor roda 4 atau lebih | I41: 1273099 | K41: =SUM(K42:K43) -> 254619800000 | L41: =SUM(L42:L43) -> 47282 | N41: =SUM(N42:N43) -> 9456400000 | O41: =N41/K41 -> 0.037139296
E42: 1) | F42: Baru | I42: 626781 | J42: 200000 | K42: =I42*J42 -> 125356200000 | L42: 6305 | M42: 200000 | N42: =L42*M42 -> 1261000000 | O42: =N42/K42 -> 0.010059335
E43: 2) | F43: Perpanjangan | I43: 646318 | J43: 200000 | K43: =I43*J43 -> 129263600000 | L43: 40977 | M43: 200000 | N43: =L43*M43 -> 8195400000 | O43: =N43/K43 -> 0.063400679
C45: 5 | D45: Penerbitan Tanda Nomor Kendaraan Bermotor (TNKB) | I45: 6000000 | K45: =SUM(K46,K47) -> 411586320000 | L45: =SUM(L46:L47) -> 271207 | N45: =SUM(N46,N47) -> 18329500000 | O45: =N45/K45 -> 0.044533793
D46: a. | E46: Kendaraan Bermotor Roda 2 atau 3 | I46: 4710342 | J46: 60000 | K46: =I46*J46 -> 282620520000 | L46: 219780 | M46: 60000 | N46: =L46*M46 -> 13186800000 | O46: =N46/K46 -> 0.046659032
D47: b. | E47: Kendaraan Bermotor Roda 4 atau lebih | I47: 1289658 | J47: 100000 | K47: =I47*J47 -> 128965800000 | L47: 51427 | M47: 100000 | N47: =L47*M47 -> 5142700000 | O47: =N47/K47 -> 0.039876463
C49: 6 | D49: Penerbitan Surat Tanda Coba Kendaraan Bermotor (STCK) | I49: 1500000 | K49: =SUM(K50:K51) -> 43861750000 | L49: =SUM(L50:L51) -> 62515 | N49: =SUM(N50:N51) -> 1730525000 | O49: =N49/K49 -> 0.03945408
D50: a. | E50: Kendaraan Bermotor Roda 2 atau 3 | I50: 1245530 | J50: 25000 | K50: =I50*J50 -> 31138250000 | L50: 55809 | M50: 25000 | N50: =L50*M50 -> 1395225000 | O50: =N50/K50 -> 0.044807431
D51: b. | E51: Kendaraan Bermotor Roda 4 atau lebih | I51: 254470 | J51: 50000 | K51: =I51*J51 -> 12723500000 | L51: 6706 | M51: 50000 | N51: =L51*M51 -> 335300000 | O51: =N51/K51 -> 0.026352812
